2025-02-17 14:03:51,821 - INFO - Starting day planner script...
2025-02-17 14:03:51,863 - ERROR - ‚ùå An error occurred: HTTPSConnectionPool(host='oauth2.googleapis.com', port=443): Max retries exceeded with url: /token (Caused by NameResolutionError("<urllib3.connection.HTTPSConnection object at 0x1039baba0>: Failed to resolve 'oauth2.googleapis.com' ([Errno 8] nodename nor servname provided, or not known)"))
2025-02-17 14:03:51,869 - ERROR - Traceback (most recent call last):
  File "/Users/jinglinli/Documents/obsidian/.venv/lib/python3.13/site-packages/urllib3/connection.py", line 198, in _new_conn
    sock = connection.create_connection(
        (self._dns_host, self.port),
    ...<2 lines>...
        socket_options=self.socket_options,
    )
  File "/Users/jinglinli/Documents/obsidian/.venv/lib/python3.13/site-packages/urllib3/util/connection.py", line 60, in create_connection
    for res in socket.getaddrinfo(host, port, family, socket.SOCK_STREAM):
               ~~~~~~~~~~~~~~~~~~^^^^^^^^^^^^^^^^^^^^^^^^^^^^^^^^^^^^^^^^
  File "/opt/homebrew/Cellar/python@3.13/3.13.1/Frameworks/Python.framework/Versions/3.13/lib/python3.13/socket.py", line 975, in getaddrinfo
    for res in _socket.getaddrinfo(host, port, family, type, proto, flags):
               ~~~~~~~~~~~~~~~~~~~^^^^^^^^^^^^^^^^^^^^^^^^^^^^^^^^^^^^^^^^
socket.gaierror: [Errno 8] nodename nor servname provided, or not known

The above exception was the direct cause of the following exception:

Traceback (most recent call last):
  File "/Users/jinglinli/Documents/obsidian/.venv/lib/python3.13/site-packages/urllib3/connectionpool.py", line 787, in urlopen
    response = self._make_request(
        conn,
    ...<10 lines>...
        **response_kw,
    )
  File "/Users/jinglinli/Documents/obsidian/.venv/lib/python3.13/site-packages/urllib3/connectionpool.py", line 488, in _make_request
    raise new_e
  File "/Users/jinglinli/Documents/obsidian/.venv/lib/python3.13/site-packages/urllib3/connectionpool.py", line 464, in _make_request
    self._validate_conn(conn)
    ~~~~~~~~~~~~~~~~~~~^^^^^^
  File "/Users/jinglinli/Documents/obsidian/.venv/lib/python3.13/site-packages/urllib3/connectionpool.py", line 1093, in _validate_conn
    conn.connect()
    ~~~~~~~~~~~~^^
  File "/Users/jinglinli/Documents/obsidian/.venv/lib/python3.13/site-packages/urllib3/connection.py", line 704, in connect
    self.sock = sock = self._new_conn()
                       ~~~~~~~~~~~~~~^^
  File "/Users/jinglinli/Documents/obsidian/.venv/lib/python3.13/site-packages/urllib3/connection.py", line 205, in _new_conn
    raise NameResolutionError(self.host, self, e) from e
urllib3.exceptions.NameResolutionError: <urllib3.connection.HTTPSConnection object at 0x1039baba0>: Failed to resolve 'oauth2.googleapis.com' ([Errno 8] nodename nor servname provided, or not known)

The above exception was the direct cause of the following exception:

Traceback (most recent call last):
  File "/Users/jinglinli/Documents/obsidian/.venv/lib/python3.13/site-packages/requests/adapters.py", line 667, in send
    resp = conn.urlopen(
        method=request.method,
    ...<9 lines>...
        chunked=chunked,
    )
  File "/Users/jinglinli/Documents/obsidian/.venv/lib/python3.13/site-packages/urllib3/connectionpool.py", line 841, in urlopen
    retries = retries.increment(
        method, url, error=new_e, _pool=self, _stacktrace=sys.exc_info()[2]
    )
  File "/Users/jinglinli/Documents/obsidian/.venv/lib/python3.13/site-packages/urllib3/util/retry.py", line 519, in increment
    raise MaxRetryError(_pool, url, reason) from reason  # type: ignore[arg-type]
    ^^^^^^^^^^^^^^^^^^^^^^^^^^^^^^^^^^^^^^^^^^^^^^^^^^^
urllib3.exceptions.MaxRetryError: HTTPSConnectionPool(host='oauth2.googleapis.com', port=443): Max retries exceeded with url: /token (Caused by NameResolutionError("<urllib3.connection.HTTPSConnection object at 0x1039baba0>: Failed to resolve 'oauth2.googleapis.com' ([Errno 8] nodename nor servname provided, or not known)"))

During handling of the above exception, another exception occurred:

Traceback (most recent call last):
  File "/Users/jinglinli/Documents/obsidian/.venv/lib/python3.13/site-packages/google/auth/transport/requests.py", line 186, in __call__
    response = self.session.request(
        method, url, data=body, headers=headers, timeout=timeout, **kwargs
    )
  File "/Users/jinglinli/Documents/obsidian/.venv/lib/python3.13/site-packages/requests/sessions.py", line 589, in request
    resp = self.send(prep, **send_kwargs)
  File "/Users/jinglinli/Documents/obsidian/.venv/lib/python3.13/site-packages/requests/sessions.py", line 703, in send
    r = adapter.send(request, **kwargs)
  File "/Users/jinglinli/Documents/obsidian/.venv/lib/python3.13/site-packages/requests/adapters.py", line 700, in send
    raise ConnectionError(e, request=request)
requests.exceptions.ConnectionError: HTTPSConnectionPool(host='oauth2.googleapis.com', port=443): Max retries exceeded with url: /token (Caused by NameResolutionError("<urllib3.connection.HTTPSConnection object at 0x1039baba0>: Failed to resolve 'oauth2.googleapis.com' ([Errno 8] nodename nor servname provided, or not known)"))

The above exception was the direct cause of the following exception:

Traceback (most recent call last):
  File "/Users/jinglinli/Documents/obsidian/day_planner/dayplanner.py", line 175, in main
    claude_schedule = call_claude(kanban_content)
  File "/Users/jinglinli/Documents/obsidian/day_planner/dayplanner.py", line 29, in call_claude
    calendar_service = GoogleCalendarService()
  File "/Users/jinglinli/Documents/obsidian/day_planner/gcal_service.py", line 18, in __init__
    self.service = self._get_calendar_service()
                   ~~~~~~~~~~~~~~~~~~~~~~~~~~^^
  File "/Users/jinglinli/Documents/obsidian/day_planner/gcal_service.py", line 43, in _get_calendar_service
    creds.refresh(Request())
    ~~~~~~~~~~~~~^^^^^^^^^^^
  File "/Users/jinglinli/Documents/obsidian/.venv/lib/python3.13/site-packages/google/oauth2/credentials.py", line 409, in refresh
    ) = reauth.refresh_grant(
        ~~~~~~~~~~~~~~~~~~~~^
        request,
        ^^^^^^^^
    ...<6 lines>...
        enable_reauth_refresh=self._enable_reauth_refresh,
        ^^^^^^^^^^^^^^^^^^^^^^^^^^^^^^^^^^^^^^^^^^^^^^^^^^
    )
    ^
  File "/Users/jinglinli/Documents/obsidian/.venv/lib/python3.13/site-packages/google/oauth2/reauth.py", line 333, in refresh_grant
    response_status_ok, response_data, retryable_error = _client._token_endpoint_request_no_throw(
                                                         ~~~~~~~~~~~~~~~~~~~~~~~~~~~~~~~~~~~~~~~~^
        request, token_uri, body, headers=metrics_header
        ^^^^^^^^^^^^^^^^^^^^^^^^^^^^^^^^^^^^^^^^^^^^^^^^
    )
    ^
  File "/Users/jinglinli/Documents/obsidian/.venv/lib/python3.13/site-packages/google/oauth2/_client.py", line 192, in _token_endpoint_request_no_throw
    response = request(
        method="POST", url=token_uri, headers=headers_to_use, body=body, **kwargs
    )
  File "/Users/jinglinli/Documents/obsidian/.venv/lib/python3.13/site-packages/google/auth/transport/requests.py", line 192, in __call__
    raise new_exc from caught_exc
google.auth.exceptions.TransportError: HTTPSConnectionPool(host='oauth2.googleapis.com', port=443): Max retries exceeded with url: /token (Caused by NameResolutionError("<urllib3.connection.HTTPSConnection object at 0x1039baba0>: Failed to resolve 'oauth2.googleapis.com' ([Errno 8] nodename nor servname provided, or not known)"))

