2025-01-30 22:00:05,934 - INFO - Starting day planner script...
2025-01-30 22:00:06,618 - INFO - ‚úÖ Successfully connected to Google Calendar
2025-01-30 22:00:06,619 - INFO - üìÖ Primary Calendar ID: c_ritfi48pp9ld7atshj6uu5q6r4@group.calendar.google.com
2025-01-30 22:00:24,937 - INFO - ‚úÖ Successfully connected to Google Calendar
2025-01-30 22:00:24,938 - INFO - üìÖ Primary Calendar ID: c_ritfi48pp9ld7atshj6uu5q6r4@group.calendar.google.com
2025-01-30 22:00:24,943 - ERROR - ‚ùå An error occurred: time data '09:00' does not match format '%I:%M%p'
2025-01-30 22:00:24,947 - ERROR - Traceback (most recent call last):
  File "/Users/jinglinli/Documents/obsidian/day_planner/dayplanner.py", line 176, in main
    processed_schedule = preprocess_schedule(claude_schedule, tomorrow)
  File "/Users/jinglinli/Documents/obsidian/day_planner/dayplanner.py", line 120, in preprocess_schedule
    datetime.datetime.strptime(start_time.strip().upper(), '%I:%M%p').time()
    ~~~~~~~~~~~~~~~~~~~~~~~~~~^^^^^^^^^^^^^^^^^^^^^^^^^^^^^^^^^^^^^^^
  File "/opt/homebrew/Cellar/python@3.13/3.13.1/Frameworks/Python.framework/Versions/3.13/lib/python3.13/_strptime.py", line 676, in _strptime_datetime
    tt, fraction, gmtoff_fraction = _strptime(data_string, format)
                                    ~~~~~~~~~^^^^^^^^^^^^^^^^^^^^^
  File "/opt/homebrew/Cellar/python@3.13/3.13.1/Frameworks/Python.framework/Versions/3.13/lib/python3.13/_strptime.py", line 455, in _strptime
    raise ValueError("time data %r does not match format %r" %
                     (data_string, format))
ValueError: time data '09:00' does not match format '%I:%M%p'

